{
 "cells": [
  {
   "cell_type": "code",
   "execution_count": 1,
   "id": "964523e5",
   "metadata": {},
   "outputs": [],
   "source": [
    "import tensorflow as tf\n",
    "from tensorflow import keras\n",
    "import matplotlib.pyplot as plt\n",
    "from tqdm import tqdm\n",
    "import numpy as np\n",
    "import cv2\n",
    "import mobilenet_ae_Unet\n",
    "import data_util\n",
    "import pandas as pd"
   ]
  },
  {
   "cell_type": "code",
   "execution_count": 2,
   "id": "3327684a",
   "metadata": {},
   "outputs": [],
   "source": [
    "mse = keras.losses.MeanSquaredError()\n",
    "ce = keras.losses.CategoricalCrossentropy()"
   ]
  },
  {
   "cell_type": "code",
   "execution_count": 3,
   "id": "6d2bdf4a",
   "metadata": {},
   "outputs": [],
   "source": [
    "def custom_loss(y_true, y_pred):\n",
    "    y_class_true = y_true[:, 0:133]\n",
    "    y_class_pred = y_pred[:, 0:133]\n",
    "    \n",
    "    y_point_true = y_true[:, 133:]\n",
    "    y_point_pred = y_pred[:, 133:]\n",
    "    \n",
    "    class_loss = ce(y_class_true, y_class_pred)\n",
    "    point_loss = mse(y_point_true, y_point_pred)\n",
    "    \n",
    "    return 0.5 * point_loss + 0.5 * class_loss"
   ]
  },
  {
   "cell_type": "code",
   "execution_count": 6,
   "id": "23163266",
   "metadata": {},
   "outputs": [
    {
     "name": "stdout",
     "output_type": "stream",
     "text": [
      "WARNING:tensorflow:`input_shape` is undefined or non-square, or `rows` is not in [96, 128, 160, 192, 224]. Weights for input shape (224, 224) will be loaded as the default.\n",
      "WARNING:tensorflow:Inconsistent references when loading the checkpoint into this object graph. Either the Trackable object references in the Python program have changed in an incompatible way, or the checkpoint was generated in an incompatible program.\n",
      "\n",
      "Two checkpoint references resolved to different objects (<tensorflow.python.keras.layers.convolutional.Conv2D object at 0x000001D8A94F6190> and <tensorflow.python.keras.layers.convolutional.ZeroPadding2D object at 0x000001D8B5335EE0>).\n",
      "WARNING:tensorflow:Inconsistent references when loading the checkpoint into this object graph. Either the Trackable object references in the Python program have changed in an incompatible way, or the checkpoint was generated in an incompatible program.\n",
      "\n",
      "Two checkpoint references resolved to different objects (<tensorflow.python.keras.layers.normalization_v2.BatchNormalization object at 0x000001D8B536F610> and <tensorflow.python.keras.layers.convolutional.Conv2D object at 0x000001D8A94F6190>).\n",
      "WARNING:tensorflow:Inconsistent references when loading the checkpoint into this object graph. Either the Trackable object references in the Python program have changed in an incompatible way, or the checkpoint was generated in an incompatible program.\n",
      "\n",
      "Two checkpoint references resolved to different objects (<tensorflow.python.keras.layers.convolutional.DepthwiseConv2D object at 0x000001D8B536FC70> and <tensorflow.python.keras.layers.advanced_activations.ReLU object at 0x000001D8F4ECE2E0>).\n",
      "WARNING:tensorflow:Inconsistent references when loading the checkpoint into this object graph. Either the Trackable object references in the Python program have changed in an incompatible way, or the checkpoint was generated in an incompatible program.\n",
      "\n",
      "Two checkpoint references resolved to different objects (<tensorflow.python.keras.layers.normalization_v2.BatchNormalization object at 0x000001D8B5541670> and <tensorflow.python.keras.layers.convolutional.DepthwiseConv2D object at 0x000001D8B536FC70>).\n",
      "WARNING:tensorflow:Inconsistent references when loading the checkpoint into this object graph. Either the Trackable object references in the Python program have changed in an incompatible way, or the checkpoint was generated in an incompatible program.\n",
      "\n",
      "Two checkpoint references resolved to different objects (<tensorflow.python.keras.layers.convolutional.Conv2D object at 0x000001D8B555A9A0> and <tensorflow.python.keras.layers.advanced_activations.ReLU object at 0x000001D8B5541400>).\n",
      "WARNING:tensorflow:Inconsistent references when loading the checkpoint into this object graph. Either the Trackable object references in the Python program have changed in an incompatible way, or the checkpoint was generated in an incompatible program.\n",
      "\n",
      "Two checkpoint references resolved to different objects (<tensorflow.python.keras.layers.normalization_v2.BatchNormalization object at 0x000001D8B5563B50> and <tensorflow.python.keras.layers.convolutional.Conv2D object at 0x000001D8B555A9A0>).\n",
      "WARNING:tensorflow:Inconsistent references when loading the checkpoint into this object graph. Either the Trackable object references in the Python program have changed in an incompatible way, or the checkpoint was generated in an incompatible program.\n",
      "\n",
      "Two checkpoint references resolved to different objects (<tensorflow.python.keras.layers.convolutional.Conv2D object at 0x000001D8B5571910> and <tensorflow.python.keras.layers.normalization_v2.BatchNormalization object at 0x000001D8B5563B50>).\n",
      "WARNING:tensorflow:Inconsistent references when loading the checkpoint into this object graph. Either the Trackable object references in the Python program have changed in an incompatible way, or the checkpoint was generated in an incompatible program.\n",
      "\n",
      "Two checkpoint references resolved to different objects (<tensorflow.python.keras.layers.normalization_v2.BatchNormalization object at 0x000001D8B557A760> and <tensorflow.python.keras.layers.convolutional.Conv2D object at 0x000001D8B5571910>).\n",
      "WARNING:tensorflow:Inconsistent references when loading the checkpoint into this object graph. Either the Trackable object references in the Python program have changed in an incompatible way, or the checkpoint was generated in an incompatible program.\n",
      "\n",
      "Two checkpoint references resolved to different objects (<tensorflow.python.keras.layers.convolutional.DepthwiseConv2D object at 0x000001D8B5593790> and <tensorflow.python.keras.layers.convolutional.ZeroPadding2D object at 0x000001D8B5587D90>).\n",
      "WARNING:tensorflow:Inconsistent references when loading the checkpoint into this object graph. Either the Trackable object references in the Python program have changed in an incompatible way, or the checkpoint was generated in an incompatible program.\n",
      "\n",
      "Two checkpoint references resolved to different objects (<tensorflow.python.keras.layers.normalization_v2.BatchNormalization object at 0x000001D8B55A0C40> and <tensorflow.python.keras.layers.convolutional.DepthwiseConv2D object at 0x000001D8B5593790>).\n",
      "WARNING:tensorflow:Inconsistent references when loading the checkpoint into this object graph. Either the Trackable object references in the Python program have changed in an incompatible way, or the checkpoint was generated in an incompatible program.\n",
      "\n",
      "Two checkpoint references resolved to different objects (<tensorflow.python.keras.layers.convolutional.Conv2D object at 0x000001D8B55ADB50> and <tensorflow.python.keras.layers.advanced_activations.ReLU object at 0x000001D8B55936A0>).\n",
      "WARNING:tensorflow:Inconsistent references when loading the checkpoint into this object graph. Either the Trackable object references in the Python program have changed in an incompatible way, or the checkpoint was generated in an incompatible program.\n",
      "\n",
      "Two checkpoint references resolved to different objects (<tensorflow.python.keras.layers.normalization_v2.BatchNormalization object at 0x000001D8B55B6C10> and <tensorflow.python.keras.layers.convolutional.Conv2D object at 0x000001D8B55ADB50>).\n",
      "WARNING:tensorflow:Inconsistent references when loading the checkpoint into this object graph. Either the Trackable object references in the Python program have changed in an incompatible way, or the checkpoint was generated in an incompatible program.\n",
      "\n",
      "Two checkpoint references resolved to different objects (<tensorflow.python.keras.layers.convolutional.Conv2D object at 0x000001D8B55C59A0> and <tensorflow.python.keras.layers.normalization_v2.BatchNormalization object at 0x000001D8B55B6C10>).\n",
      "WARNING:tensorflow:Inconsistent references when loading the checkpoint into this object graph. Either the Trackable object references in the Python program have changed in an incompatible way, or the checkpoint was generated in an incompatible program.\n",
      "\n",
      "Two checkpoint references resolved to different objects (<tensorflow.python.keras.layers.normalization_v2.BatchNormalization object at 0x000001D8B55CD7F0> and <tensorflow.python.keras.layers.convolutional.Conv2D object at 0x000001D8B55C59A0>).\n",
      "WARNING:tensorflow:Inconsistent references when loading the checkpoint into this object graph. Either the Trackable object references in the Python program have changed in an incompatible way, or the checkpoint was generated in an incompatible program.\n",
      "\n",
      "Two checkpoint references resolved to different objects (<tensorflow.python.keras.layers.convolutional.DepthwiseConv2D object at 0x000001D8B55DCFA0> and <tensorflow.python.keras.layers.advanced_activations.ReLU object at 0x000001D8B55CD910>).\n",
      "WARNING:tensorflow:Inconsistent references when loading the checkpoint into this object graph. Either the Trackable object references in the Python program have changed in an incompatible way, or the checkpoint was generated in an incompatible program.\n",
      "\n",
      "Two checkpoint references resolved to different objects (<tensorflow.python.keras.layers.normalization_v2.BatchNormalization object at 0x000001D8B55E5910> and <tensorflow.python.keras.layers.convolutional.DepthwiseConv2D object at 0x000001D8B55DCFA0>).\n",
      "WARNING:tensorflow:Inconsistent references when loading the checkpoint into this object graph. Either the Trackable object references in the Python program have changed in an incompatible way, or the checkpoint was generated in an incompatible program.\n",
      "\n",
      "Two checkpoint references resolved to different objects (<tensorflow.python.keras.layers.convolutional.Conv2D object at 0x000001D8B55FFC70> and <tensorflow.python.keras.layers.advanced_activations.ReLU object at 0x000001D8B55F5490>).\n"
     ]
    },
    {
     "name": "stdout",
     "output_type": "stream",
     "text": [
      "WARNING:tensorflow:Inconsistent references when loading the checkpoint into this object graph. Either the Trackable object references in the Python program have changed in an incompatible way, or the checkpoint was generated in an incompatible program.\n",
      "\n",
      "Two checkpoint references resolved to different objects (<tensorflow.python.keras.layers.normalization_v2.BatchNormalization object at 0x000001D8B5606BE0> and <tensorflow.python.keras.layers.convolutional.Conv2D object at 0x000001D8B55FFC70>).\n",
      "WARNING:tensorflow:Inconsistent references when loading the checkpoint into this object graph. Either the Trackable object references in the Python program have changed in an incompatible way, or the checkpoint was generated in an incompatible program.\n",
      "\n",
      "Two checkpoint references resolved to different objects (<tensorflow.python.keras.layers.convolutional.Conv2D object at 0x000001D8B5616BB0> and <tensorflow.python.keras.layers.merge.Add object at 0x000001D8B5606AC0>).\n",
      "WARNING:tensorflow:Inconsistent references when loading the checkpoint into this object graph. Either the Trackable object references in the Python program have changed in an incompatible way, or the checkpoint was generated in an incompatible program.\n",
      "\n",
      "Two checkpoint references resolved to different objects (<tensorflow.python.keras.layers.normalization_v2.BatchNormalization object at 0x000001D8B5626F10> and <tensorflow.python.keras.layers.convolutional.Conv2D object at 0x000001D8B5616BB0>).\n",
      "WARNING:tensorflow:Inconsistent references when loading the checkpoint into this object graph. Either the Trackable object references in the Python program have changed in an incompatible way, or the checkpoint was generated in an incompatible program.\n",
      "\n",
      "Two checkpoint references resolved to different objects (<tensorflow.python.keras.layers.convolutional.DepthwiseConv2D object at 0x000001D8B5639850> and <tensorflow.python.keras.layers.convolutional.ZeroPadding2D object at 0x000001D8B562EE50>).\n",
      "WARNING:tensorflow:Inconsistent references when loading the checkpoint into this object graph. Either the Trackable object references in the Python program have changed in an incompatible way, or the checkpoint was generated in an incompatible program.\n",
      "\n",
      "Two checkpoint references resolved to different objects (<tensorflow.python.keras.layers.normalization_v2.BatchNormalization object at 0x000001D8B563E430> and <tensorflow.python.keras.layers.convolutional.DepthwiseConv2D object at 0x000001D8B5639850>).\n",
      "WARNING:tensorflow:Inconsistent references when loading the checkpoint into this object graph. Either the Trackable object references in the Python program have changed in an incompatible way, or the checkpoint was generated in an incompatible program.\n",
      "\n",
      "Two checkpoint references resolved to different objects (<tensorflow.python.keras.layers.convolutional.Conv2D object at 0x000001D8B5654C10> and <tensorflow.python.keras.layers.advanced_activations.ReLU object at 0x000001D8B5639760>).\n",
      "WARNING:tensorflow:Inconsistent references when loading the checkpoint into this object graph. Either the Trackable object references in the Python program have changed in an incompatible way, or the checkpoint was generated in an incompatible program.\n",
      "\n",
      "Two checkpoint references resolved to different objects (<tensorflow.python.keras.layers.normalization_v2.BatchNormalization object at 0x000001D8B565DCD0> and <tensorflow.python.keras.layers.convolutional.Conv2D object at 0x000001D8B5654C10>).\n",
      "WARNING:tensorflow:Inconsistent references when loading the checkpoint into this object graph. Either the Trackable object references in the Python program have changed in an incompatible way, or the checkpoint was generated in an incompatible program.\n",
      "\n",
      "Two checkpoint references resolved to different objects (<tensorflow.python.keras.layers.convolutional.Conv2D object at 0x000001D8B5668A60> and <tensorflow.python.keras.layers.normalization_v2.BatchNormalization object at 0x000001D8B565DCD0>).\n",
      "WARNING:tensorflow:Inconsistent references when loading the checkpoint into this object graph. Either the Trackable object references in the Python program have changed in an incompatible way, or the checkpoint was generated in an incompatible program.\n",
      "\n",
      "Two checkpoint references resolved to different objects (<tensorflow.python.keras.layers.normalization_v2.BatchNormalization object at 0x000001D8B56728B0> and <tensorflow.python.keras.layers.convolutional.Conv2D object at 0x000001D8B5668A60>).\n",
      "WARNING:tensorflow:Inconsistent references when loading the checkpoint into this object graph. Either the Trackable object references in the Python program have changed in an incompatible way, or the checkpoint was generated in an incompatible program.\n",
      "\n",
      "Two checkpoint references resolved to different objects (<tensorflow.python.keras.layers.convolutional.DepthwiseConv2D object at 0x000001D8B5681F40> and <tensorflow.python.keras.layers.advanced_activations.ReLU object at 0x000001D8B5672610>).\n",
      "WARNING:tensorflow:Inconsistent references when loading the checkpoint into this object graph. Either the Trackable object references in the Python program have changed in an incompatible way, or the checkpoint was generated in an incompatible program.\n",
      "\n",
      "Two checkpoint references resolved to different objects (<tensorflow.python.keras.layers.normalization_v2.BatchNormalization object at 0x000001D8B5691910> and <tensorflow.python.keras.layers.convolutional.DepthwiseConv2D object at 0x000001D8B5681F40>).\n",
      "WARNING:tensorflow:Inconsistent references when loading the checkpoint into this object graph. Either the Trackable object references in the Python program have changed in an incompatible way, or the checkpoint was generated in an incompatible program.\n",
      "\n",
      "Two checkpoint references resolved to different objects (<tensorflow.python.keras.layers.convolutional.Conv2D object at 0x000001D8B56A6D00> and <tensorflow.python.keras.layers.advanced_activations.ReLU object at 0x000001D8B5699AF0>).\n",
      "WARNING:tensorflow:Inconsistent references when loading the checkpoint into this object graph. Either the Trackable object references in the Python program have changed in an incompatible way, or the checkpoint was generated in an incompatible program.\n",
      "\n",
      "Two checkpoint references resolved to different objects (<tensorflow.python.keras.layers.normalization_v2.BatchNormalization object at 0x000001D8B56ADC70> and <tensorflow.python.keras.layers.convolutional.Conv2D object at 0x000001D8B56A6D00>).\n",
      "WARNING:tensorflow:Inconsistent references when loading the checkpoint into this object graph. Either the Trackable object references in the Python program have changed in an incompatible way, or the checkpoint was generated in an incompatible program.\n",
      "\n",
      "Two checkpoint references resolved to different objects (<tensorflow.python.keras.layers.convolutional.Conv2D object at 0x000001D8B56BFC40> and <tensorflow.python.keras.layers.merge.Add object at 0x000001D8B56ADB50>).\n",
      "WARNING:tensorflow:Inconsistent references when loading the checkpoint into this object graph. Either the Trackable object references in the Python program have changed in an incompatible way, or the checkpoint was generated in an incompatible program.\n",
      "\n",
      "Two checkpoint references resolved to different objects (<tensorflow.python.keras.layers.normalization_v2.BatchNormalization object at 0x000001D8B6B6BEE0> and <tensorflow.python.keras.layers.convolutional.Conv2D object at 0x000001D8B56BFC40>).\n",
      "WARNING:tensorflow:Inconsistent references when loading the checkpoint into this object graph. Either the Trackable object references in the Python program have changed in an incompatible way, or the checkpoint was generated in an incompatible program.\n",
      "\n",
      "Two checkpoint references resolved to different objects (<tensorflow.python.keras.layers.convolutional.DepthwiseConv2D object at 0x000001D8B6B77F40> and <tensorflow.python.keras.layers.advanced_activations.ReLU object at 0x000001D8B6B6BEB0>).\n",
      "WARNING:tensorflow:Inconsistent references when loading the checkpoint into this object graph. Either the Trackable object references in the Python program have changed in an incompatible way, or the checkpoint was generated in an incompatible program.\n",
      "\n",
      "Two checkpoint references resolved to different objects (<tensorflow.python.keras.layers.normalization_v2.BatchNormalization object at 0x000001D8B6B84910> and <tensorflow.python.keras.layers.convolutional.DepthwiseConv2D object at 0x000001D8B6B77F40>).\n"
     ]
    },
    {
     "name": "stdout",
     "output_type": "stream",
     "text": [
      "WARNING:tensorflow:Inconsistent references when loading the checkpoint into this object graph. Either the Trackable object references in the Python program have changed in an incompatible way, or the checkpoint was generated in an incompatible program.\n",
      "\n",
      "Two checkpoint references resolved to different objects (<tensorflow.python.keras.layers.convolutional.Conv2D object at 0x000001D8B6B9BD00> and <tensorflow.python.keras.layers.advanced_activations.ReLU object at 0x000001D8B6B8EAF0>).\n",
      "WARNING:tensorflow:Inconsistent references when loading the checkpoint into this object graph. Either the Trackable object references in the Python program have changed in an incompatible way, or the checkpoint was generated in an incompatible program.\n",
      "\n",
      "Two checkpoint references resolved to different objects (<tensorflow.python.keras.layers.normalization_v2.BatchNormalization object at 0x000001D8B6BA1C70> and <tensorflow.python.keras.layers.convolutional.Conv2D object at 0x000001D8B6B9BD00>).\n",
      "WARNING:tensorflow:Inconsistent references when loading the checkpoint into this object graph. Either the Trackable object references in the Python program have changed in an incompatible way, or the checkpoint was generated in an incompatible program.\n",
      "\n",
      "Two checkpoint references resolved to different objects (<tensorflow.python.keras.layers.convolutional.Conv2D object at 0x000001D8B6BB2C40> and <tensorflow.python.keras.layers.merge.Add object at 0x000001D8B6BA1B50>).\n",
      "WARNING:tensorflow:Inconsistent references when loading the checkpoint into this object graph. Either the Trackable object references in the Python program have changed in an incompatible way, or the checkpoint was generated in an incompatible program.\n",
      "\n",
      "Two checkpoint references resolved to different objects (<tensorflow.python.keras.layers.normalization_v2.BatchNormalization object at 0x000001D8B6BBEEE0> and <tensorflow.python.keras.layers.convolutional.Conv2D object at 0x000001D8B6BB2C40>).\n",
      "WARNING:tensorflow:Inconsistent references when loading the checkpoint into this object graph. Either the Trackable object references in the Python program have changed in an incompatible way, or the checkpoint was generated in an incompatible program.\n",
      "\n",
      "Two checkpoint references resolved to different objects (<tensorflow.python.keras.layers.convolutional.DepthwiseConv2D object at 0x000001D8B6BD38E0> and <tensorflow.python.keras.layers.convolutional.ZeroPadding2D object at 0x000001D8B6BC9E20>).\n",
      "WARNING:tensorflow:Inconsistent references when loading the checkpoint into this object graph. Either the Trackable object references in the Python program have changed in an incompatible way, or the checkpoint was generated in an incompatible program.\n",
      "\n",
      "Two checkpoint references resolved to different objects (<tensorflow.python.keras.layers.normalization_v2.BatchNormalization object at 0x000001D8B6BE1D90> and <tensorflow.python.keras.layers.convolutional.DepthwiseConv2D object at 0x000001D8B6BD38E0>).\n",
      "WARNING:tensorflow:Inconsistent references when loading the checkpoint into this object graph. Either the Trackable object references in the Python program have changed in an incompatible way, or the checkpoint was generated in an incompatible program.\n",
      "\n",
      "Two checkpoint references resolved to different objects (<tensorflow.python.keras.layers.convolutional.Conv2D object at 0x000001D8B6BEFCA0> and <tensorflow.python.keras.layers.advanced_activations.ReLU object at 0x000001D8B6BD37F0>).\n",
      "WARNING:tensorflow:Inconsistent references when loading the checkpoint into this object graph. Either the Trackable object references in the Python program have changed in an incompatible way, or the checkpoint was generated in an incompatible program.\n",
      "\n",
      "Two checkpoint references resolved to different objects (<tensorflow.python.keras.layers.normalization_v2.BatchNormalization object at 0x000001D8B6BF8D60> and <tensorflow.python.keras.layers.convolutional.Conv2D object at 0x000001D8B6BEFCA0>).\n",
      "WARNING:tensorflow:Inconsistent references when loading the checkpoint into this object graph. Either the Trackable object references in the Python program have changed in an incompatible way, or the checkpoint was generated in an incompatible program.\n",
      "\n",
      "Two checkpoint references resolved to different objects (<tensorflow.python.keras.layers.convolutional.Conv2D object at 0x000001D8B6C01AF0> and <tensorflow.python.keras.layers.normalization_v2.BatchNormalization object at 0x000001D8B6BF8D60>).\n",
      "WARNING:tensorflow:Inconsistent references when loading the checkpoint into this object graph. Either the Trackable object references in the Python program have changed in an incompatible way, or the checkpoint was generated in an incompatible program.\n",
      "\n",
      "Two checkpoint references resolved to different objects (<tensorflow.python.keras.layers.normalization_v2.BatchNormalization object at 0x000001D8B6C0D940> and <tensorflow.python.keras.layers.convolutional.Conv2D object at 0x000001D8B6C01AF0>).\n",
      "WARNING:tensorflow:Inconsistent references when loading the checkpoint into this object graph. Either the Trackable object references in the Python program have changed in an incompatible way, or the checkpoint was generated in an incompatible program.\n",
      "\n",
      "Two checkpoint references resolved to different objects (<tensorflow.python.keras.layers.convolutional.DepthwiseConv2D object at 0x000001D8B6C1CF70> and <tensorflow.python.keras.layers.advanced_activations.ReLU object at 0x000001D8B6C0D6A0>).\n",
      "WARNING:tensorflow:Inconsistent references when loading the checkpoint into this object graph. Either the Trackable object references in the Python program have changed in an incompatible way, or the checkpoint was generated in an incompatible program.\n",
      "\n",
      "Two checkpoint references resolved to different objects (<tensorflow.python.keras.layers.normalization_v2.BatchNormalization object at 0x000001D8B6C28A30> and <tensorflow.python.keras.layers.convolutional.DepthwiseConv2D object at 0x000001D8B6C1CF70>).\n",
      "WARNING:tensorflow:Inconsistent references when loading the checkpoint into this object graph. Either the Trackable object references in the Python program have changed in an incompatible way, or the checkpoint was generated in an incompatible program.\n",
      "\n",
      "Two checkpoint references resolved to different objects (<tensorflow.python.keras.layers.convolutional.Conv2D object at 0x000001D8B6C3FD90> and <tensorflow.python.keras.layers.advanced_activations.ReLU object at 0x000001D8B6C345B0>).\n",
      "WARNING:tensorflow:Inconsistent references when loading the checkpoint into this object graph. Either the Trackable object references in the Python program have changed in an incompatible way, or the checkpoint was generated in an incompatible program.\n",
      "\n",
      "Two checkpoint references resolved to different objects (<tensorflow.python.keras.layers.normalization_v2.BatchNormalization object at 0x000001D8B6C4BA90> and <tensorflow.python.keras.layers.convolutional.Conv2D object at 0x000001D8B6C3FD90>).\n",
      "WARNING:tensorflow:Inconsistent references when loading the checkpoint into this object graph. Either the Trackable object references in the Python program have changed in an incompatible way, or the checkpoint was generated in an incompatible program.\n",
      "\n",
      "Two checkpoint references resolved to different objects (<tensorflow.python.keras.layers.convolutional.Conv2D object at 0x000001D8B6C58CD0> and <tensorflow.python.keras.layers.merge.Add object at 0x000001D8B6C4BE80>).\n",
      "WARNING:tensorflow:Inconsistent references when loading the checkpoint into this object graph. Either the Trackable object references in the Python program have changed in an incompatible way, or the checkpoint was generated in an incompatible program.\n",
      "\n",
      "Two checkpoint references resolved to different objects (<tensorflow.python.keras.layers.normalization_v2.BatchNormalization object at 0x000001D8B6C65E80> and <tensorflow.python.keras.layers.convolutional.Conv2D object at 0x000001D8B6C58CD0>).\n",
      "WARNING:tensorflow:Inconsistent references when loading the checkpoint into this object graph. Either the Trackable object references in the Python program have changed in an incompatible way, or the checkpoint was generated in an incompatible program.\n",
      "\n",
      "Two checkpoint references resolved to different objects (<tensorflow.python.keras.layers.convolutional.DepthwiseConv2D object at 0x000001D8B6C6FF70> and <tensorflow.python.keras.layers.advanced_activations.ReLU object at 0x000001D8B6C65F70>).\n"
     ]
    },
    {
     "name": "stdout",
     "output_type": "stream",
     "text": [
      "WARNING:tensorflow:Inconsistent references when loading the checkpoint into this object graph. Either the Trackable object references in the Python program have changed in an incompatible way, or the checkpoint was generated in an incompatible program.\n",
      "\n",
      "Two checkpoint references resolved to different objects (<tensorflow.python.keras.layers.normalization_v2.BatchNormalization object at 0x000001D8B6C7AA30> and <tensorflow.python.keras.layers.convolutional.DepthwiseConv2D object at 0x000001D8B6C6FF70>).\n",
      "WARNING:tensorflow:Inconsistent references when loading the checkpoint into this object graph. Either the Trackable object references in the Python program have changed in an incompatible way, or the checkpoint was generated in an incompatible program.\n",
      "\n",
      "Two checkpoint references resolved to different objects (<tensorflow.python.keras.layers.convolutional.Conv2D object at 0x000001D8B6C93D90> and <tensorflow.python.keras.layers.advanced_activations.ReLU object at 0x000001D8B6C8A5B0>).\n",
      "WARNING:tensorflow:Inconsistent references when loading the checkpoint into this object graph. Either the Trackable object references in the Python program have changed in an incompatible way, or the checkpoint was generated in an incompatible program.\n",
      "\n",
      "Two checkpoint references resolved to different objects (<tensorflow.python.keras.layers.normalization_v2.BatchNormalization object at 0x000001D8B6CA0A90> and <tensorflow.python.keras.layers.convolutional.Conv2D object at 0x000001D8B6C93D90>).\n",
      "WARNING:tensorflow:Inconsistent references when loading the checkpoint into this object graph. Either the Trackable object references in the Python program have changed in an incompatible way, or the checkpoint was generated in an incompatible program.\n",
      "\n",
      "Two checkpoint references resolved to different objects (<tensorflow.python.keras.layers.convolutional.Conv2D object at 0x000001D8B6CADCD0> and <tensorflow.python.keras.layers.merge.Add object at 0x000001D8B6CA0E80>).\n",
      "WARNING:tensorflow:Inconsistent references when loading the checkpoint into this object graph. Either the Trackable object references in the Python program have changed in an incompatible way, or the checkpoint was generated in an incompatible program.\n",
      "\n",
      "Two checkpoint references resolved to different objects (<tensorflow.python.keras.layers.normalization_v2.BatchNormalization object at 0x000001D8B6CBBE80> and <tensorflow.python.keras.layers.convolutional.Conv2D object at 0x000001D8B6CADCD0>).\n",
      "WARNING:tensorflow:Inconsistent references when loading the checkpoint into this object graph. Either the Trackable object references in the Python program have changed in an incompatible way, or the checkpoint was generated in an incompatible program.\n",
      "\n",
      "Two checkpoint references resolved to different objects (<tensorflow.python.keras.layers.convolutional.DepthwiseConv2D object at 0x000001D8B6CC3F70> and <tensorflow.python.keras.layers.advanced_activations.ReLU object at 0x000001D8B6CBBF70>).\n",
      "WARNING:tensorflow:Inconsistent references when loading the checkpoint into this object graph. Either the Trackable object references in the Python program have changed in an incompatible way, or the checkpoint was generated in an incompatible program.\n",
      "\n",
      "Two checkpoint references resolved to different objects (<tensorflow.python.keras.layers.normalization_v2.BatchNormalization object at 0x000001D8B6CCCA30> and <tensorflow.python.keras.layers.convolutional.DepthwiseConv2D object at 0x000001D8B6CC3F70>).\n",
      "WARNING:tensorflow:Inconsistent references when loading the checkpoint into this object graph. Either the Trackable object references in the Python program have changed in an incompatible way, or the checkpoint was generated in an incompatible program.\n",
      "\n",
      "Two checkpoint references resolved to different objects (<tensorflow.python.keras.layers.convolutional.Conv2D object at 0x000001D8B6CE7D90> and <tensorflow.python.keras.layers.advanced_activations.ReLU object at 0x000001D8B6CDC5B0>).\n",
      "WARNING:tensorflow:Inconsistent references when loading the checkpoint into this object graph. Either the Trackable object references in the Python program have changed in an incompatible way, or the checkpoint was generated in an incompatible program.\n",
      "\n",
      "Two checkpoint references resolved to different objects (<tensorflow.python.keras.layers.normalization_v2.BatchNormalization object at 0x000001D8B6CF4A90> and <tensorflow.python.keras.layers.convolutional.Conv2D object at 0x000001D8B6CE7D90>).\n",
      "WARNING:tensorflow:Inconsistent references when loading the checkpoint into this object graph. Either the Trackable object references in the Python program have changed in an incompatible way, or the checkpoint was generated in an incompatible program.\n",
      "\n",
      "Two checkpoint references resolved to different objects (<tensorflow.python.keras.layers.convolutional.Conv2D object at 0x000001D8B6CFECD0> and <tensorflow.python.keras.layers.merge.Add object at 0x000001D8B6CF4E80>).\n",
      "WARNING:tensorflow:Inconsistent references when loading the checkpoint into this object graph. Either the Trackable object references in the Python program have changed in an incompatible way, or the checkpoint was generated in an incompatible program.\n",
      "\n",
      "Two checkpoint references resolved to different objects (<tensorflow.python.keras.layers.normalization_v2.BatchNormalization object at 0x000001D8B6D0CE80> and <tensorflow.python.keras.layers.convolutional.Conv2D object at 0x000001D8B6CFECD0>).\n",
      "WARNING:tensorflow:Inconsistent references when loading the checkpoint into this object graph. Either the Trackable object references in the Python program have changed in an incompatible way, or the checkpoint was generated in an incompatible program.\n",
      "\n",
      "Two checkpoint references resolved to different objects (<tensorflow.python.keras.layers.convolutional.DepthwiseConv2D object at 0x000001D8B6D16F70> and <tensorflow.python.keras.layers.advanced_activations.ReLU object at 0x000001D8B6D0CF70>).\n",
      "WARNING:tensorflow:Inconsistent references when loading the checkpoint into this object graph. Either the Trackable object references in the Python program have changed in an incompatible way, or the checkpoint was generated in an incompatible program.\n",
      "\n",
      "Two checkpoint references resolved to different objects (<tensorflow.python.keras.layers.normalization_v2.BatchNormalization object at 0x000001D8B6D20A30> and <tensorflow.python.keras.layers.convolutional.DepthwiseConv2D object at 0x000001D8B6D16F70>).\n",
      "WARNING:tensorflow:Inconsistent references when loading the checkpoint into this object graph. Either the Trackable object references in the Python program have changed in an incompatible way, or the checkpoint was generated in an incompatible program.\n",
      "\n",
      "Two checkpoint references resolved to different objects (<tensorflow.python.keras.layers.convolutional.Conv2D object at 0x000001D8B6D3BD90> and <tensorflow.python.keras.layers.advanced_activations.ReLU object at 0x000001D8B6D2E5B0>).\n",
      "WARNING:tensorflow:Inconsistent references when loading the checkpoint into this object graph. Either the Trackable object references in the Python program have changed in an incompatible way, or the checkpoint was generated in an incompatible program.\n",
      "\n",
      "Two checkpoint references resolved to different objects (<tensorflow.python.keras.layers.normalization_v2.BatchNormalization object at 0x000001D8B6D46A90> and <tensorflow.python.keras.layers.convolutional.Conv2D object at 0x000001D8B6D3BD90>).\n",
      "WARNING:tensorflow:Inconsistent references when loading the checkpoint into this object graph. Either the Trackable object references in the Python program have changed in an incompatible way, or the checkpoint was generated in an incompatible program.\n",
      "\n",
      "Two checkpoint references resolved to different objects (<tensorflow.python.keras.layers.convolutional.Conv2D object at 0x000001D8B6D537C0> and <tensorflow.python.keras.layers.normalization_v2.BatchNormalization object at 0x000001D8B6D46A90>).\n",
      "WARNING:tensorflow:Inconsistent references when loading the checkpoint into this object graph. Either the Trackable object references in the Python program have changed in an incompatible way, or the checkpoint was generated in an incompatible program.\n",
      "\n",
      "Two checkpoint references resolved to different objects (<tensorflow.python.keras.layers.normalization_v2.BatchNormalization object at 0x000001D8B6D5B640> and <tensorflow.python.keras.layers.convolutional.Conv2D object at 0x000001D8B6D537C0>).\n"
     ]
    },
    {
     "name": "stdout",
     "output_type": "stream",
     "text": [
      "WARNING:tensorflow:Inconsistent references when loading the checkpoint into this object graph. Either the Trackable object references in the Python program have changed in an incompatible way, or the checkpoint was generated in an incompatible program.\n",
      "\n",
      "Two checkpoint references resolved to different objects (<tensorflow.python.keras.layers.convolutional.DepthwiseConv2D object at 0x000001D8B7D39D90> and <tensorflow.python.keras.layers.advanced_activations.ReLU object at 0x000001D8B7D30EE0>).\n",
      "WARNING:tensorflow:Inconsistent references when loading the checkpoint into this object graph. Either the Trackable object references in the Python program have changed in an incompatible way, or the checkpoint was generated in an incompatible program.\n",
      "\n",
      "Two checkpoint references resolved to different objects (<tensorflow.python.keras.layers.normalization_v2.BatchNormalization object at 0x000001D8B7D47700> and <tensorflow.python.keras.layers.convolutional.DepthwiseConv2D object at 0x000001D8B7D39D90>).\n",
      "WARNING:tensorflow:Inconsistent references when loading the checkpoint into this object graph. Either the Trackable object references in the Python program have changed in an incompatible way, or the checkpoint was generated in an incompatible program.\n",
      "\n",
      "Two checkpoint references resolved to different objects (<tensorflow.python.keras.layers.convolutional.Conv2D object at 0x000001D8B7D5DA60> and <tensorflow.python.keras.layers.advanced_activations.ReLU object at 0x000001D8B7D55070>).\n",
      "WARNING:tensorflow:Inconsistent references when loading the checkpoint into this object graph. Either the Trackable object references in the Python program have changed in an incompatible way, or the checkpoint was generated in an incompatible program.\n",
      "\n",
      "Two checkpoint references resolved to different objects (<tensorflow.python.keras.layers.normalization_v2.BatchNormalization object at 0x000001D8B7D659A0> and <tensorflow.python.keras.layers.convolutional.Conv2D object at 0x000001D8B7D5DA60>).\n",
      "WARNING:tensorflow:Inconsistent references when loading the checkpoint into this object graph. Either the Trackable object references in the Python program have changed in an incompatible way, or the checkpoint was generated in an incompatible program.\n",
      "\n",
      "Two checkpoint references resolved to different objects (<tensorflow.python.keras.layers.convolutional.Conv2D object at 0x000001D8B7D79910> and <tensorflow.python.keras.layers.merge.Add object at 0x000001D8B7D65DF0>).\n",
      "WARNING:tensorflow:Inconsistent references when loading the checkpoint into this object graph. Either the Trackable object references in the Python program have changed in an incompatible way, or the checkpoint was generated in an incompatible program.\n",
      "\n",
      "Two checkpoint references resolved to different objects (<tensorflow.python.keras.layers.normalization_v2.BatchNormalization object at 0x000001D8B7D84F10> and <tensorflow.python.keras.layers.convolutional.Conv2D object at 0x000001D8B7D79910>).\n",
      "WARNING:tensorflow:Inconsistent references when loading the checkpoint into this object graph. Either the Trackable object references in the Python program have changed in an incompatible way, or the checkpoint was generated in an incompatible program.\n",
      "\n",
      "Two checkpoint references resolved to different objects (<tensorflow.python.keras.layers.convolutional.DepthwiseConv2D object at 0x000001D8B7D8EDC0> and <tensorflow.python.keras.layers.advanced_activations.ReLU object at 0x000001D8B7D84E80>).\n",
      "WARNING:tensorflow:Inconsistent references when loading the checkpoint into this object graph. Either the Trackable object references in the Python program have changed in an incompatible way, or the checkpoint was generated in an incompatible program.\n",
      "\n",
      "Two checkpoint references resolved to different objects (<tensorflow.python.keras.layers.normalization_v2.BatchNormalization object at 0x000001D8B7D96730> and <tensorflow.python.keras.layers.convolutional.DepthwiseConv2D object at 0x000001D8B7D8EDC0>).\n",
      "WARNING:tensorflow:Inconsistent references when loading the checkpoint into this object graph. Either the Trackable object references in the Python program have changed in an incompatible way, or the checkpoint was generated in an incompatible program.\n",
      "\n",
      "Two checkpoint references resolved to different objects (<tensorflow.python.keras.layers.convolutional.Conv2D object at 0x000001D8B7DB3A90> and <tensorflow.python.keras.layers.advanced_activations.ReLU object at 0x000001D8B7DA80D0>).\n",
      "WARNING:tensorflow:Inconsistent references when loading the checkpoint into this object graph. Either the Trackable object references in the Python program have changed in an incompatible way, or the checkpoint was generated in an incompatible program.\n",
      "\n",
      "Two checkpoint references resolved to different objects (<tensorflow.python.keras.layers.normalization_v2.BatchNormalization object at 0x000001D8B7DB99D0> and <tensorflow.python.keras.layers.convolutional.Conv2D object at 0x000001D8B7DB3A90>).\n",
      "WARNING:tensorflow:Inconsistent references when loading the checkpoint into this object graph. Either the Trackable object references in the Python program have changed in an incompatible way, or the checkpoint was generated in an incompatible program.\n",
      "\n",
      "Two checkpoint references resolved to different objects (<tensorflow.python.keras.layers.convolutional.Conv2D object at 0x000001D8B7DCE910> and <tensorflow.python.keras.layers.merge.Add object at 0x000001D8B7DB9E20>).\n",
      "WARNING:tensorflow:Inconsistent references when loading the checkpoint into this object graph. Either the Trackable object references in the Python program have changed in an incompatible way, or the checkpoint was generated in an incompatible program.\n",
      "\n",
      "Two checkpoint references resolved to different objects (<tensorflow.python.keras.layers.normalization_v2.BatchNormalization object at 0x000001D8B7DD7F10> and <tensorflow.python.keras.layers.convolutional.Conv2D object at 0x000001D8B7DCE910>).\n",
      "WARNING:tensorflow:Inconsistent references when loading the checkpoint into this object graph. Either the Trackable object references in the Python program have changed in an incompatible way, or the checkpoint was generated in an incompatible program.\n",
      "\n",
      "Two checkpoint references resolved to different objects (<tensorflow.python.keras.layers.convolutional.DepthwiseConv2D object at 0x000001D8B7DED670> and <tensorflow.python.keras.layers.convolutional.ZeroPadding2D object at 0x000001D8B7DE3C70>).\n",
      "WARNING:tensorflow:Inconsistent references when loading the checkpoint into this object graph. Either the Trackable object references in the Python program have changed in an incompatible way, or the checkpoint was generated in an incompatible program.\n",
      "\n",
      "Two checkpoint references resolved to different objects (<tensorflow.python.keras.layers.normalization_v2.BatchNormalization object at 0x000001D8B7DF00D0> and <tensorflow.python.keras.layers.convolutional.DepthwiseConv2D object at 0x000001D8B7DED670>).\n",
      "WARNING:tensorflow:Inconsistent references when loading the checkpoint into this object graph. Either the Trackable object references in the Python program have changed in an incompatible way, or the checkpoint was generated in an incompatible program.\n",
      "\n",
      "Two checkpoint references resolved to different objects (<tensorflow.python.keras.layers.convolutional.Conv2D object at 0x000001D8B7E06910> and <tensorflow.python.keras.layers.advanced_activations.ReLU object at 0x000001D8B7DF9B50>).\n",
      "WARNING:tensorflow:Inconsistent references when loading the checkpoint into this object graph. Either the Trackable object references in the Python program have changed in an incompatible way, or the checkpoint was generated in an incompatible program.\n",
      "\n",
      "Two checkpoint references resolved to different objects (<tensorflow.python.keras.layers.normalization_v2.BatchNormalization object at 0x000001D8B7E12D60> and <tensorflow.python.keras.layers.convolutional.Conv2D object at 0x000001D8B7E06910>).\n",
      "WARNING:tensorflow:Inconsistent references when loading the checkpoint into this object graph. Either the Trackable object references in the Python program have changed in an incompatible way, or the checkpoint was generated in an incompatible program.\n",
      "\n",
      "Two checkpoint references resolved to different objects (<tensorflow.python.keras.layers.convolutional.Conv2D object at 0x000001D8B7E1D880> and <tensorflow.python.keras.layers.normalization_v2.BatchNormalization object at 0x000001D8B7E12D60>).\n"
     ]
    },
    {
     "name": "stdout",
     "output_type": "stream",
     "text": [
      "WARNING:tensorflow:Inconsistent references when loading the checkpoint into this object graph. Either the Trackable object references in the Python program have changed in an incompatible way, or the checkpoint was generated in an incompatible program.\n",
      "\n",
      "Two checkpoint references resolved to different objects (<tensorflow.python.keras.layers.normalization_v2.BatchNormalization object at 0x000001D8B7E276D0> and <tensorflow.python.keras.layers.convolutional.Conv2D object at 0x000001D8B7E1D880>).\n",
      "WARNING:tensorflow:Inconsistent references when loading the checkpoint into this object graph. Either the Trackable object references in the Python program have changed in an incompatible way, or the checkpoint was generated in an incompatible program.\n",
      "\n",
      "Two checkpoint references resolved to different objects (<tensorflow.python.keras.layers.convolutional.DepthwiseConv2D object at 0x000001D8B7E35E50> and <tensorflow.python.keras.layers.advanced_activations.ReLU object at 0x000001D8B7E27430>).\n",
      "WARNING:tensorflow:Inconsistent references when loading the checkpoint into this object graph. Either the Trackable object references in the Python program have changed in an incompatible way, or the checkpoint was generated in an incompatible program.\n",
      "\n",
      "Two checkpoint references resolved to different objects (<tensorflow.python.keras.layers.normalization_v2.BatchNormalization object at 0x000001D8B7E407C0> and <tensorflow.python.keras.layers.convolutional.DepthwiseConv2D object at 0x000001D8B7E35E50>).\n",
      "WARNING:tensorflow:Inconsistent references when loading the checkpoint into this object graph. Either the Trackable object references in the Python program have changed in an incompatible way, or the checkpoint was generated in an incompatible program.\n",
      "\n",
      "Two checkpoint references resolved to different objects (<tensorflow.python.keras.layers.convolutional.Conv2D object at 0x000001D8B7E56B20> and <tensorflow.python.keras.layers.advanced_activations.ReLU object at 0x000001D8B7E4F340>).\n",
      "WARNING:tensorflow:Inconsistent references when loading the checkpoint into this object graph. Either the Trackable object references in the Python program have changed in an incompatible way, or the checkpoint was generated in an incompatible program.\n",
      "\n",
      "Two checkpoint references resolved to different objects (<tensorflow.python.keras.layers.normalization_v2.BatchNormalization object at 0x000001D8B7E5F970> and <tensorflow.python.keras.layers.convolutional.Conv2D object at 0x000001D8B7E56B20>).\n",
      "WARNING:tensorflow:Inconsistent references when loading the checkpoint into this object graph. Either the Trackable object references in the Python program have changed in an incompatible way, or the checkpoint was generated in an incompatible program.\n",
      "\n",
      "Two checkpoint references resolved to different objects (<tensorflow.python.keras.layers.convolutional.Conv2D object at 0x000001D8B7E72A60> and <tensorflow.python.keras.layers.merge.Add object at 0x000001D8B7E5FEE0>).\n",
      "WARNING:tensorflow:Inconsistent references when loading the checkpoint into this object graph. Either the Trackable object references in the Python program have changed in an incompatible way, or the checkpoint was generated in an incompatible program.\n",
      "\n",
      "Two checkpoint references resolved to different objects (<tensorflow.python.keras.layers.normalization_v2.BatchNormalization object at 0x000001D8B7E7EDC0> and <tensorflow.python.keras.layers.convolutional.Conv2D object at 0x000001D8B7E72A60>).\n",
      "WARNING:tensorflow:Inconsistent references when loading the checkpoint into this object graph. Either the Trackable object references in the Python program have changed in an incompatible way, or the checkpoint was generated in an incompatible program.\n",
      "\n",
      "Two checkpoint references resolved to different objects (<tensorflow.python.keras.layers.convolutional.DepthwiseConv2D object at 0x000001D8B7E8AE50> and <tensorflow.python.keras.layers.advanced_activations.ReLU object at 0x000001D8B7E7ED60>).\n",
      "WARNING:tensorflow:Inconsistent references when loading the checkpoint into this object graph. Either the Trackable object references in the Python program have changed in an incompatible way, or the checkpoint was generated in an incompatible program.\n",
      "\n",
      "Two checkpoint references resolved to different objects (<tensorflow.python.keras.layers.normalization_v2.BatchNormalization object at 0x000001D8B7E937C0> and <tensorflow.python.keras.layers.convolutional.DepthwiseConv2D object at 0x000001D8B7E8AE50>).\n",
      "WARNING:tensorflow:Inconsistent references when loading the checkpoint into this object graph. Either the Trackable object references in the Python program have changed in an incompatible way, or the checkpoint was generated in an incompatible program.\n",
      "\n",
      "Two checkpoint references resolved to different objects (<tensorflow.python.keras.layers.convolutional.Conv2D object at 0x000001D8B7EACB20> and <tensorflow.python.keras.layers.advanced_activations.ReLU object at 0x000001D8B7EA2340>).\n",
      "WARNING:tensorflow:Inconsistent references when loading the checkpoint into this object graph. Either the Trackable object references in the Python program have changed in an incompatible way, or the checkpoint was generated in an incompatible program.\n",
      "\n",
      "Two checkpoint references resolved to different objects (<tensorflow.python.keras.layers.normalization_v2.BatchNormalization object at 0x000001D8B7EB3970> and <tensorflow.python.keras.layers.convolutional.Conv2D object at 0x000001D8B7EACB20>).\n",
      "WARNING:tensorflow:Inconsistent references when loading the checkpoint into this object graph. Either the Trackable object references in the Python program have changed in an incompatible way, or the checkpoint was generated in an incompatible program.\n",
      "\n",
      "Two checkpoint references resolved to different objects (<tensorflow.python.keras.layers.convolutional.Conv2D object at 0x000001D8B7EC6A60> and <tensorflow.python.keras.layers.merge.Add object at 0x000001D8B7EB3EE0>).\n",
      "WARNING:tensorflow:Inconsistent references when loading the checkpoint into this object graph. Either the Trackable object references in the Python program have changed in an incompatible way, or the checkpoint was generated in an incompatible program.\n",
      "\n",
      "Two checkpoint references resolved to different objects (<tensorflow.python.keras.layers.normalization_v2.BatchNormalization object at 0x000001D8B7ED2DC0> and <tensorflow.python.keras.layers.convolutional.Conv2D object at 0x000001D8B7EC6A60>).\n",
      "WARNING:tensorflow:Inconsistent references when loading the checkpoint into this object graph. Either the Trackable object references in the Python program have changed in an incompatible way, or the checkpoint was generated in an incompatible program.\n",
      "\n",
      "Two checkpoint references resolved to different objects (<tensorflow.python.keras.layers.convolutional.DepthwiseConv2D object at 0x000001D8B7EDDE50> and <tensorflow.python.keras.layers.advanced_activations.ReLU object at 0x000001D8B7ED2D60>).\n",
      "WARNING:tensorflow:Inconsistent references when loading the checkpoint into this object graph. Either the Trackable object references in the Python program have changed in an incompatible way, or the checkpoint was generated in an incompatible program.\n",
      "\n",
      "Two checkpoint references resolved to different objects (<tensorflow.python.keras.layers.normalization_v2.BatchNormalization object at 0x000001D8B7EE77C0> and <tensorflow.python.keras.layers.convolutional.DepthwiseConv2D object at 0x000001D8B7EDDE50>).\n",
      "WARNING:tensorflow:Inconsistent references when loading the checkpoint into this object graph. Either the Trackable object references in the Python program have changed in an incompatible way, or the checkpoint was generated in an incompatible program.\n",
      "\n",
      "Two checkpoint references resolved to different objects (<tensorflow.python.keras.layers.convolutional.Conv2D object at 0x000001D8B7F00B20> and <tensorflow.python.keras.layers.advanced_activations.ReLU object at 0x000001D8B7EF5340>).\n",
      "WARNING:tensorflow:Inconsistent references when loading the checkpoint into this object graph. Either the Trackable object references in the Python program have changed in an incompatible way, or the checkpoint was generated in an incompatible program.\n",
      "\n",
      "Two checkpoint references resolved to different objects (<tensorflow.python.keras.layers.normalization_v2.BatchNormalization object at 0x000001D8B7F07970> and <tensorflow.python.keras.layers.convolutional.Conv2D object at 0x000001D8B7F00B20>).\n"
     ]
    },
    {
     "name": "stdout",
     "output_type": "stream",
     "text": [
      "WARNING:tensorflow:Inconsistent references when loading the checkpoint into this object graph. Either the Trackable object references in the Python program have changed in an incompatible way, or the checkpoint was generated in an incompatible program.\n",
      "\n",
      "Two checkpoint references resolved to different objects (<tensorflow.python.keras.layers.convolutional.Conv2D object at 0x000001D8B7F3A310> and <tensorflow.python.keras.layers.normalization_v2.BatchNormalization object at 0x000001D8B7F07970>).\n",
      "WARNING:tensorflow:Inconsistent references when loading the checkpoint into this object graph. Either the Trackable object references in the Python program have changed in an incompatible way, or the checkpoint was generated in an incompatible program.\n",
      "\n",
      "Two checkpoint references resolved to different objects (<tensorflow.python.keras.layers.normalization_v2.BatchNormalization object at 0x000001D8B7F33970> and <tensorflow.python.keras.layers.convolutional.Conv2D object at 0x000001D8B7F3A310>).\n",
      "WARNING:tensorflow:Inconsistent references when loading the checkpoint into this object graph. Either the Trackable object references in the Python program have changed in an incompatible way, or the checkpoint was generated in an incompatible program.\n",
      "\n",
      "Two checkpoint references resolved to different objects (<tensorflow.python.keras.layers.convolutional.Conv2DTranspose object at 0x000001D8B7F83520> and <tensorflow.python.keras.layers.normalization_v2.BatchNormalization object at 0x000001D8B7F33970>).\n",
      "WARNING:tensorflow:Inconsistent references when loading the checkpoint into this object graph. Either the Trackable object references in the Python program have changed in an incompatible way, or the checkpoint was generated in an incompatible program.\n",
      "\n",
      "Two checkpoint references resolved to different objects (<tensorflow.python.keras.layers.normalization_v2.BatchNormalization object at 0x000001D8B7F83A60> and <tensorflow.python.keras.layers.convolutional.Conv2DTranspose object at 0x000001D8B7F83520>).\n",
      "WARNING:tensorflow:Inconsistent references when loading the checkpoint into this object graph. Either the Trackable object references in the Python program have changed in an incompatible way, or the checkpoint was generated in an incompatible program.\n",
      "\n",
      "Two checkpoint references resolved to different objects (<tensorflow.python.keras.layers.convolutional.Conv2DTranspose object at 0x000001D8B7F92E50> and <tensorflow.python.keras.layers.normalization_v2.BatchNormalization object at 0x000001D8B7F83A60>).\n",
      "WARNING:tensorflow:Inconsistent references when loading the checkpoint into this object graph. Either the Trackable object references in the Python program have changed in an incompatible way, or the checkpoint was generated in an incompatible program.\n",
      "\n",
      "Two checkpoint references resolved to different objects (<tensorflow.python.keras.layers.convolutional.Conv2D object at 0x000001D8B7FA3D00> and <tensorflow.python.keras.layers.merge.Concatenate object at 0x000001D8B7F92CD0>).\n",
      "WARNING:tensorflow:Inconsistent references when loading the checkpoint into this object graph. Either the Trackable object references in the Python program have changed in an incompatible way, or the checkpoint was generated in an incompatible program.\n",
      "\n",
      "Two checkpoint references resolved to different objects (<tensorflow.python.keras.layers.normalization_v2.BatchNormalization object at 0x000001D8B80F29D0> and <tensorflow.python.keras.layers.convolutional.Conv2D object at 0x000001D8B7FA3D00>).\n",
      "WARNING:tensorflow:Inconsistent references when loading the checkpoint into this object graph. Either the Trackable object references in the Python program have changed in an incompatible way, or the checkpoint was generated in an incompatible program.\n",
      "\n",
      "Two checkpoint references resolved to different objects (<tensorflow.python.keras.layers.convolutional.Conv2D object at 0x000001D8B80F9FA0> and <tensorflow.python.keras.layers.core.Dropout object at 0x000001D8B80F9820>).\n",
      "WARNING:tensorflow:Inconsistent references when loading the checkpoint into this object graph. Either the Trackable object references in the Python program have changed in an incompatible way, or the checkpoint was generated in an incompatible program.\n",
      "\n",
      "Two checkpoint references resolved to different objects (<tensorflow.python.keras.layers.normalization_v2.BatchNormalization object at 0x000001D8B80FFA60> and <tensorflow.python.keras.layers.convolutional.Conv2D object at 0x000001D8B80F9FA0>).\n",
      "WARNING:tensorflow:Inconsistent references when loading the checkpoint into this object graph. Either the Trackable object references in the Python program have changed in an incompatible way, or the checkpoint was generated in an incompatible program.\n",
      "\n",
      "Two checkpoint references resolved to different objects (<tensorflow.python.keras.layers.convolutional.Conv2DTranspose object at 0x000001D8B8120490> and <tensorflow.python.keras.layers.normalization_v2.BatchNormalization object at 0x000001D8B80FFA60>).\n",
      "WARNING:tensorflow:Inconsistent references when loading the checkpoint into this object graph. Either the Trackable object references in the Python program have changed in an incompatible way, or the checkpoint was generated in an incompatible program.\n",
      "\n",
      "Two checkpoint references resolved to different objects (<tensorflow.python.keras.layers.convolutional.Conv2D object at 0x000001D8B8128550> and <tensorflow.python.keras.layers.merge.Concatenate object at 0x000001D8B812BE80>).\n",
      "WARNING:tensorflow:Inconsistent references when loading the checkpoint into this object graph. Either the Trackable object references in the Python program have changed in an incompatible way, or the checkpoint was generated in an incompatible program.\n",
      "\n",
      "Two checkpoint references resolved to different objects (<tensorflow.python.keras.layers.normalization_v2.BatchNormalization object at 0x000001D8B81284F0> and <tensorflow.python.keras.layers.convolutional.Conv2D object at 0x000001D8B8128550>).\n",
      "WARNING:tensorflow:Inconsistent references when loading the checkpoint into this object graph. Either the Trackable object references in the Python program have changed in an incompatible way, or the checkpoint was generated in an incompatible program.\n",
      "\n",
      "Two checkpoint references resolved to different objects (<tensorflow.python.keras.layers.convolutional.Conv2D object at 0x000001D8B8148130> and <tensorflow.python.keras.layers.core.Dropout object at 0x000001D8B8148190>).\n",
      "WARNING:tensorflow:Inconsistent references when loading the checkpoint into this object graph. Either the Trackable object references in the Python program have changed in an incompatible way, or the checkpoint was generated in an incompatible program.\n",
      "\n",
      "Two checkpoint references resolved to different objects (<tensorflow.python.keras.layers.normalization_v2.BatchNormalization object at 0x000001D8B81486A0> and <tensorflow.python.keras.layers.convolutional.Conv2D object at 0x000001D8B8148130>).\n",
      "WARNING:tensorflow:Inconsistent references when loading the checkpoint into this object graph. Either the Trackable object references in the Python program have changed in an incompatible way, or the checkpoint was generated in an incompatible program.\n",
      "\n",
      "Two checkpoint references resolved to different objects (<tensorflow.python.keras.layers.convolutional.Conv2DTranspose object at 0x000001D8B816BB50> and <tensorflow.python.keras.layers.normalization_v2.BatchNormalization object at 0x000001D8B81486A0>).\n",
      "WARNING:tensorflow:Inconsistent references when loading the checkpoint into this object graph. Either the Trackable object references in the Python program have changed in an incompatible way, or the checkpoint was generated in an incompatible program.\n",
      "\n",
      "Two checkpoint references resolved to different objects (<tensorflow.python.keras.layers.convolutional.Conv2D object at 0x000001D8B8178AC0> and <tensorflow.python.keras.layers.merge.Concatenate object at 0x000001D8B816B070>).\n",
      "WARNING:tensorflow:Inconsistent references when loading the checkpoint into this object graph. Either the Trackable object references in the Python program have changed in an incompatible way, or the checkpoint was generated in an incompatible program.\n",
      "\n",
      "Two checkpoint references resolved to different objects (<tensorflow.python.keras.layers.normalization_v2.BatchNormalization object at 0x000001D8B81783D0> and <tensorflow.python.keras.layers.convolutional.Conv2D object at 0x000001D8B8178AC0>).\n"
     ]
    },
    {
     "name": "stdout",
     "output_type": "stream",
     "text": [
      "WARNING:tensorflow:Inconsistent references when loading the checkpoint into this object graph. Either the Trackable object references in the Python program have changed in an incompatible way, or the checkpoint was generated in an incompatible program.\n",
      "\n",
      "Two checkpoint references resolved to different objects (<tensorflow.python.keras.layers.convolutional.Conv2D object at 0x000001D8B81977F0> and <tensorflow.python.keras.layers.core.Dropout object at 0x000001D8B81975E0>).\n",
      "WARNING:tensorflow:Inconsistent references when loading the checkpoint into this object graph. Either the Trackable object references in the Python program have changed in an incompatible way, or the checkpoint was generated in an incompatible program.\n",
      "\n",
      "Two checkpoint references resolved to different objects (<tensorflow.python.keras.layers.normalization_v2.BatchNormalization object at 0x000001D8B8197A30> and <tensorflow.python.keras.layers.convolutional.Conv2D object at 0x000001D8B81977F0>).\n",
      "WARNING:tensorflow:Inconsistent references when loading the checkpoint into this object graph. Either the Trackable object references in the Python program have changed in an incompatible way, or the checkpoint was generated in an incompatible program.\n",
      "\n",
      "Two checkpoint references resolved to different objects (<tensorflow.python.keras.layers.convolutional.Conv2DTranspose object at 0x000001D8B81BF250> and <tensorflow.python.keras.layers.normalization_v2.BatchNormalization object at 0x000001D8B8197A30>).\n",
      "WARNING:tensorflow:Inconsistent references when loading the checkpoint into this object graph. Either the Trackable object references in the Python program have changed in an incompatible way, or the checkpoint was generated in an incompatible program.\n",
      "\n",
      "Two checkpoint references resolved to different objects (<tensorflow.python.keras.layers.convolutional.Conv2D object at 0x000001D8B81C7340> and <tensorflow.python.keras.layers.merge.Concatenate object at 0x000001D8B81CBF70>).\n",
      "WARNING:tensorflow:Inconsistent references when loading the checkpoint into this object graph. Either the Trackable object references in the Python program have changed in an incompatible way, or the checkpoint was generated in an incompatible program.\n",
      "\n",
      "Two checkpoint references resolved to different objects (<tensorflow.python.keras.layers.normalization_v2.BatchNormalization object at 0x000001D8B81D7F70> and <tensorflow.python.keras.layers.convolutional.Conv2D object at 0x000001D8B81C7340>).\n",
      "WARNING:tensorflow:Inconsistent references when loading the checkpoint into this object graph. Either the Trackable object references in the Python program have changed in an incompatible way, or the checkpoint was generated in an incompatible program.\n",
      "\n",
      "Two checkpoint references resolved to different objects (<tensorflow.python.keras.layers.convolutional.Conv2D object at 0x000001D8B81E2EE0> and <tensorflow.python.keras.layers.core.Dropout object at 0x000001D8B81E2CD0>).\n",
      "WARNING:tensorflow:Inconsistent references when loading the checkpoint into this object graph. Either the Trackable object references in the Python program have changed in an incompatible way, or the checkpoint was generated in an incompatible program.\n",
      "\n",
      "Two checkpoint references resolved to different objects (<tensorflow.python.keras.layers.normalization_v2.BatchNormalization object at 0x000001D8B8204EE0> and <tensorflow.python.keras.layers.convolutional.Conv2D object at 0x000001D8B81E2EE0>).\n",
      "WARNING:tensorflow:Inconsistent references when loading the checkpoint into this object graph. Either the Trackable object references in the Python program have changed in an incompatible way, or the checkpoint was generated in an incompatible program.\n",
      "\n",
      "Two checkpoint references resolved to different objects (<tensorflow.python.keras.layers.convolutional.Conv2DTranspose object at 0x000001D8B820C940> and <tensorflow.python.keras.layers.normalization_v2.BatchNormalization object at 0x000001D8B8204EE0>).\n",
      "WARNING:tensorflow:Inconsistent references when loading the checkpoint into this object graph. Either the Trackable object references in the Python program have changed in an incompatible way, or the checkpoint was generated in an incompatible program.\n",
      "\n",
      "Two checkpoint references resolved to different objects (<tensorflow.python.keras.layers.convolutional.Conv2D object at 0x000001D8B820CF10> and <tensorflow.python.keras.layers.convolutional.Conv2DTranspose object at 0x000001D8B820C940>).\n",
      "WARNING:tensorflow:Inconsistent references when loading the checkpoint into this object graph. Either the Trackable object references in the Python program have changed in an incompatible way, or the checkpoint was generated in an incompatible program.\n",
      "\n",
      "Two checkpoint references resolved to different objects (<tensorflow.python.keras.layers.normalization_v2.BatchNormalization object at 0x000001D8B820C1F0> and <tensorflow.python.keras.layers.convolutional.Conv2D object at 0x000001D8B820CF10>).\n",
      "WARNING:tensorflow:Inconsistent references when loading the checkpoint into this object graph. Either the Trackable object references in the Python program have changed in an incompatible way, or the checkpoint was generated in an incompatible program.\n",
      "\n",
      "Two checkpoint references resolved to different objects (<tensorflow.python.keras.layers.convolutional.Conv2D object at 0x000001D8B8235250> and <tensorflow.python.keras.layers.core.Dropout object at 0x000001D8B8235040>).\n",
      "WARNING:tensorflow:Inconsistent references when loading the checkpoint into this object graph. Either the Trackable object references in the Python program have changed in an incompatible way, or the checkpoint was generated in an incompatible program.\n",
      "\n",
      "Two checkpoint references resolved to different objects (<tensorflow.python.keras.layers.normalization_v2.BatchNormalization object at 0x000001D8B823C250> and <tensorflow.python.keras.layers.convolutional.Conv2D object at 0x000001D8B8235250>).\n",
      "WARNING:tensorflow:Inconsistent references when loading the checkpoint into this object graph. Either the Trackable object references in the Python program have changed in an incompatible way, or the checkpoint was generated in an incompatible program.\n",
      "\n",
      "Two checkpoint references resolved to different objects (<tensorflow.python.keras.layers.convolutional.Conv2D object at 0x000001D8B82569D0> and <tensorflow.python.keras.layers.normalization_v2.BatchNormalization object at 0x000001D8B823C250>).\n"
     ]
    }
   ],
   "source": [
    "# encoder = tf.keras.applications.mobilenet_v2.MobileNetV2(\n",
    "#     input_shape=(256,256,3), alpha=1.0, include_top=None, weights='imagenet',\n",
    "#     pooling=None, classes=1    \n",
    "# )\n",
    "encoder = mobilenet_ae_Unet.MobileNetV2_UNet().build_model(20)\n",
    "encoder.load_weights('trained_ckpt/mobileNetAE_15')\n",
    "last_layer = encoder.get_layer('encoder_last_layer')#the name of the last layer you want from the model)\n",
    "last_output = last_layer.output\n",
    "inputs = encoder.input\n",
    "encoder = tf.keras.Model(inputs, last_output)"
   ]
  },
  {
   "cell_type": "code",
   "execution_count": 7,
   "id": "474f49ff",
   "metadata": {},
   "outputs": [
    {
     "name": "stdout",
     "output_type": "stream",
     "text": [
      "Model: \"functional_9\"\n",
      "__________________________________________________________________________________________________\n",
      "Layer (type)                    Output Shape         Param #     Connected to                     \n",
      "==================================================================================================\n",
      "input_4 (InputLayer)            [(None, 256, 256, 3) 0                                            \n",
      "__________________________________________________________________________________________________\n",
      "functional_7 (Functional)       (None, 8, 8, 1280)   2257984     input_4[0][0]                    \n",
      "__________________________________________________________________________________________________\n",
      "global_average_pooling2d (Globa (None, 1280)         0           functional_7[0][0]               \n",
      "__________________________________________________________________________________________________\n",
      "branch1_class (Dense)           (None, 133)          170373      global_average_pooling2d[0][0]   \n",
      "__________________________________________________________________________________________________\n",
      "branch2_landmark (Dense)        (None, 16)           20496       global_average_pooling2d[0][0]   \n",
      "__________________________________________________________________________________________________\n",
      "concatenate_12 (Concatenate)    (None, 149)          0           branch1_class[0][0]              \n",
      "                                                                 branch2_landmark[0][0]           \n",
      "==================================================================================================\n",
      "Total params: 2,448,853\n",
      "Trainable params: 2,414,741\n",
      "Non-trainable params: 34,112\n",
      "__________________________________________________________________________________________________\n"
     ]
    }
   ],
   "source": [
    "batch_size=16\n",
    "\n",
    "inputs = keras.layers.Input(shape=(224,224,3))\n",
    "\n",
    "encoder_output = encoder(inputs)\n",
    "# flatten = keras.layers.Flatten()(encoder_output)\n",
    "gap = keras.layers.GlobalAveragePooling2D()(encoder_output)\n",
    "\n",
    "# branch1_class = keras.layers.Dense(133,activation='softmax',name='branch1_class')(flatten)\n",
    "branch1_class = keras.layers.Dense(133,activation='softmax',name='branch1_class')(gap)\n",
    "\n",
    "# branch2_landmark = keras.layers.Dense(16,name='branch2_landmark')(flatten)\n",
    "branch2_landmark = keras.layers.Dense(16,name='branch2_landmark')(gap)\n",
    "\n",
    "out= keras.layers.concatenate([branch1_class,branch2_landmark])       # concatnate?\n",
    "\n",
    "model = keras.models.Model(inputs, out)\n",
    "model.compile(loss=custom_loss,\n",
    "            optimizer='adam'\n",
    "            )\n",
    "model.summary()"
   ]
  },
  {
   "cell_type": "code",
   "execution_count": 8,
   "id": "71fe860a",
   "metadata": {},
   "outputs": [],
   "source": [
    "ds = data_util.get_cu_dataset(train_type='class', batch_size=batch_size)"
   ]
  },
  {
   "cell_type": "code",
   "execution_count": 9,
   "id": "3a185341",
   "metadata": {},
   "outputs": [
    {
     "name": "stdout",
     "output_type": "stream",
     "text": [
      "(16, 256, 256, 3)\n",
      "(16, 149)\n"
     ]
    }
   ],
   "source": [
    "for i in ds.take(1):\n",
    "    print(i[0].shape)\n",
    "    print(i[1].shape)"
   ]
  },
  {
   "cell_type": "code",
   "execution_count": 10,
   "id": "ddbb2b7a",
   "metadata": {},
   "outputs": [
    {
     "data": {
      "text/plain": [
       "478"
      ]
     },
     "execution_count": 10,
     "metadata": {},
     "output_type": "execute_result"
    }
   ],
   "source": [
    "ds_size = len(list(ds))\n",
    "ds_size"
   ]
  },
  {
   "cell_type": "code",
   "execution_count": 11,
   "id": "a5ceafc0",
   "metadata": {},
   "outputs": [],
   "source": [
    "train_size = int(0.7 * ds_size)\n",
    "val_size = int(0.15 * ds_size)\n",
    "test_size = int(0.15 * ds_size)\n",
    "\n",
    "train_ds = ds.take(train_size)\n",
    "test_ds = ds.skip(train_size)\n",
    "val_ds = test_ds.skip(val_size)\n",
    "test_ds = test_ds.take(test_size)"
   ]
  },
  {
   "cell_type": "code",
   "execution_count": 12,
   "id": "729da37e",
   "metadata": {},
   "outputs": [
    {
     "data": {
      "text/plain": [
       "(334, 73, 71)"
      ]
     },
     "execution_count": 12,
     "metadata": {},
     "output_type": "execute_result"
    }
   ],
   "source": [
    "len(list(train_ds)), len(list(val_ds)), len(list(test_ds))"
   ]
  },
  {
   "cell_type": "code",
   "execution_count": 13,
   "id": "37156649",
   "metadata": {},
   "outputs": [],
   "source": [
    "ckpt_path = 'mobilenetv2_multi'\n",
    "callbacks_list = [\n",
    "    # accuracy 기준 가장 높은 모델의 weight 저장\n",
    "    tf.keras.callbacks.ModelCheckpoint(\n",
    "        filepath = ckpt_path,\n",
    "        monitor='val_loss',\n",
    "        mode='min',\n",
    "        save_weights_only=True,\n",
    "        save_best_only=True\n",
    "    ),\n",
    "    # EarlyStopping\n",
    "    # tf.keras.callbacks.EarlyStopping(\n",
    "    #    monitor='val_loss',\n",
    "    #    mode='min',\n",
    "    #    verbose=1, \n",
    "    #    patience=20\n",
    "    # )\n",
    "]"
   ]
  },
  {
   "cell_type": "code",
   "execution_count": 14,
   "id": "590e49f2",
   "metadata": {},
   "outputs": [
    {
     "name": "stdout",
     "output_type": "stream",
     "text": [
      "Epoch 1/100\n",
      "      6/Unknown - 8s 1s/step - loss: 6371.0171"
     ]
    },
    {
     "ename": "KeyboardInterrupt",
     "evalue": "",
     "output_type": "error",
     "traceback": [
      "\u001b[1;31m---------------------------------------------------------------------------\u001b[0m",
      "\u001b[1;31mKeyboardInterrupt\u001b[0m                         Traceback (most recent call last)",
      "\u001b[1;32m~\\AppData\\Local\\Temp/ipykernel_1948/4262252040.py\u001b[0m in \u001b[0;36m<module>\u001b[1;34m\u001b[0m\n\u001b[1;32m----> 1\u001b[1;33m \u001b[0mhist\u001b[0m \u001b[1;33m=\u001b[0m \u001b[0mmodel\u001b[0m\u001b[1;33m.\u001b[0m\u001b[0mfit\u001b[0m\u001b[1;33m(\u001b[0m\u001b[0mtrain_ds\u001b[0m\u001b[1;33m,\u001b[0m \u001b[0mvalidation_data\u001b[0m\u001b[1;33m=\u001b[0m\u001b[0mval_ds\u001b[0m\u001b[1;33m,\u001b[0m \u001b[0mepochs\u001b[0m\u001b[1;33m=\u001b[0m\u001b[1;36m100\u001b[0m\u001b[1;33m,\u001b[0m \u001b[0mcallbacks\u001b[0m\u001b[1;33m=\u001b[0m\u001b[0mcallbacks_list\u001b[0m\u001b[1;33m)\u001b[0m\u001b[1;33m\u001b[0m\u001b[1;33m\u001b[0m\u001b[0m\n\u001b[0m",
      "\u001b[1;32m~\\anaconda3\\envs\\landmark\\lib\\site-packages\\tensorflow\\python\\keras\\engine\\training.py\u001b[0m in \u001b[0;36m_method_wrapper\u001b[1;34m(self, *args, **kwargs)\u001b[0m\n\u001b[0;32m    106\u001b[0m   \u001b[1;32mdef\u001b[0m \u001b[0m_method_wrapper\u001b[0m\u001b[1;33m(\u001b[0m\u001b[0mself\u001b[0m\u001b[1;33m,\u001b[0m \u001b[1;33m*\u001b[0m\u001b[0margs\u001b[0m\u001b[1;33m,\u001b[0m \u001b[1;33m**\u001b[0m\u001b[0mkwargs\u001b[0m\u001b[1;33m)\u001b[0m\u001b[1;33m:\u001b[0m\u001b[1;33m\u001b[0m\u001b[1;33m\u001b[0m\u001b[0m\n\u001b[0;32m    107\u001b[0m     \u001b[1;32mif\u001b[0m \u001b[1;32mnot\u001b[0m \u001b[0mself\u001b[0m\u001b[1;33m.\u001b[0m\u001b[0m_in_multi_worker_mode\u001b[0m\u001b[1;33m(\u001b[0m\u001b[1;33m)\u001b[0m\u001b[1;33m:\u001b[0m  \u001b[1;31m# pylint: disable=protected-access\u001b[0m\u001b[1;33m\u001b[0m\u001b[1;33m\u001b[0m\u001b[0m\n\u001b[1;32m--> 108\u001b[1;33m       \u001b[1;32mreturn\u001b[0m \u001b[0mmethod\u001b[0m\u001b[1;33m(\u001b[0m\u001b[0mself\u001b[0m\u001b[1;33m,\u001b[0m \u001b[1;33m*\u001b[0m\u001b[0margs\u001b[0m\u001b[1;33m,\u001b[0m \u001b[1;33m**\u001b[0m\u001b[0mkwargs\u001b[0m\u001b[1;33m)\u001b[0m\u001b[1;33m\u001b[0m\u001b[1;33m\u001b[0m\u001b[0m\n\u001b[0m\u001b[0;32m    109\u001b[0m \u001b[1;33m\u001b[0m\u001b[0m\n\u001b[0;32m    110\u001b[0m     \u001b[1;31m# Running inside `run_distribute_coordinator` already.\u001b[0m\u001b[1;33m\u001b[0m\u001b[1;33m\u001b[0m\u001b[1;33m\u001b[0m\u001b[0m\n",
      "\u001b[1;32m~\\anaconda3\\envs\\landmark\\lib\\site-packages\\tensorflow\\python\\keras\\engine\\training.py\u001b[0m in \u001b[0;36mfit\u001b[1;34m(self, x, y, batch_size, epochs, verbose, callbacks, validation_split, validation_data, shuffle, class_weight, sample_weight, initial_epoch, steps_per_epoch, validation_steps, validation_batch_size, validation_freq, max_queue_size, workers, use_multiprocessing)\u001b[0m\n\u001b[0;32m   1096\u001b[0m                 batch_size=batch_size):\n\u001b[0;32m   1097\u001b[0m               \u001b[0mcallbacks\u001b[0m\u001b[1;33m.\u001b[0m\u001b[0mon_train_batch_begin\u001b[0m\u001b[1;33m(\u001b[0m\u001b[0mstep\u001b[0m\u001b[1;33m)\u001b[0m\u001b[1;33m\u001b[0m\u001b[1;33m\u001b[0m\u001b[0m\n\u001b[1;32m-> 1098\u001b[1;33m               \u001b[0mtmp_logs\u001b[0m \u001b[1;33m=\u001b[0m \u001b[0mtrain_function\u001b[0m\u001b[1;33m(\u001b[0m\u001b[0miterator\u001b[0m\u001b[1;33m)\u001b[0m\u001b[1;33m\u001b[0m\u001b[1;33m\u001b[0m\u001b[0m\n\u001b[0m\u001b[0;32m   1099\u001b[0m               \u001b[1;32mif\u001b[0m \u001b[0mdata_handler\u001b[0m\u001b[1;33m.\u001b[0m\u001b[0mshould_sync\u001b[0m\u001b[1;33m:\u001b[0m\u001b[1;33m\u001b[0m\u001b[1;33m\u001b[0m\u001b[0m\n\u001b[0;32m   1100\u001b[0m                 \u001b[0mcontext\u001b[0m\u001b[1;33m.\u001b[0m\u001b[0masync_wait\u001b[0m\u001b[1;33m(\u001b[0m\u001b[1;33m)\u001b[0m\u001b[1;33m\u001b[0m\u001b[1;33m\u001b[0m\u001b[0m\n",
      "\u001b[1;32m~\\anaconda3\\envs\\landmark\\lib\\site-packages\\tensorflow\\python\\eager\\def_function.py\u001b[0m in \u001b[0;36m__call__\u001b[1;34m(self, *args, **kwds)\u001b[0m\n\u001b[0;32m    778\u001b[0m       \u001b[1;32melse\u001b[0m\u001b[1;33m:\u001b[0m\u001b[1;33m\u001b[0m\u001b[1;33m\u001b[0m\u001b[0m\n\u001b[0;32m    779\u001b[0m         \u001b[0mcompiler\u001b[0m \u001b[1;33m=\u001b[0m \u001b[1;34m\"nonXla\"\u001b[0m\u001b[1;33m\u001b[0m\u001b[1;33m\u001b[0m\u001b[0m\n\u001b[1;32m--> 780\u001b[1;33m         \u001b[0mresult\u001b[0m \u001b[1;33m=\u001b[0m \u001b[0mself\u001b[0m\u001b[1;33m.\u001b[0m\u001b[0m_call\u001b[0m\u001b[1;33m(\u001b[0m\u001b[1;33m*\u001b[0m\u001b[0margs\u001b[0m\u001b[1;33m,\u001b[0m \u001b[1;33m**\u001b[0m\u001b[0mkwds\u001b[0m\u001b[1;33m)\u001b[0m\u001b[1;33m\u001b[0m\u001b[1;33m\u001b[0m\u001b[0m\n\u001b[0m\u001b[0;32m    781\u001b[0m \u001b[1;33m\u001b[0m\u001b[0m\n\u001b[0;32m    782\u001b[0m       \u001b[0mnew_tracing_count\u001b[0m \u001b[1;33m=\u001b[0m \u001b[0mself\u001b[0m\u001b[1;33m.\u001b[0m\u001b[0m_get_tracing_count\u001b[0m\u001b[1;33m(\u001b[0m\u001b[1;33m)\u001b[0m\u001b[1;33m\u001b[0m\u001b[1;33m\u001b[0m\u001b[0m\n",
      "\u001b[1;32m~\\anaconda3\\envs\\landmark\\lib\\site-packages\\tensorflow\\python\\eager\\def_function.py\u001b[0m in \u001b[0;36m_call\u001b[1;34m(self, *args, **kwds)\u001b[0m\n\u001b[0;32m    805\u001b[0m       \u001b[1;31m# In this case we have created variables on the first call, so we run the\u001b[0m\u001b[1;33m\u001b[0m\u001b[1;33m\u001b[0m\u001b[1;33m\u001b[0m\u001b[0m\n\u001b[0;32m    806\u001b[0m       \u001b[1;31m# defunned version which is guaranteed to never create variables.\u001b[0m\u001b[1;33m\u001b[0m\u001b[1;33m\u001b[0m\u001b[1;33m\u001b[0m\u001b[0m\n\u001b[1;32m--> 807\u001b[1;33m       \u001b[1;32mreturn\u001b[0m \u001b[0mself\u001b[0m\u001b[1;33m.\u001b[0m\u001b[0m_stateless_fn\u001b[0m\u001b[1;33m(\u001b[0m\u001b[1;33m*\u001b[0m\u001b[0margs\u001b[0m\u001b[1;33m,\u001b[0m \u001b[1;33m**\u001b[0m\u001b[0mkwds\u001b[0m\u001b[1;33m)\u001b[0m  \u001b[1;31m# pylint: disable=not-callable\u001b[0m\u001b[1;33m\u001b[0m\u001b[1;33m\u001b[0m\u001b[0m\n\u001b[0m\u001b[0;32m    808\u001b[0m     \u001b[1;32melif\u001b[0m \u001b[0mself\u001b[0m\u001b[1;33m.\u001b[0m\u001b[0m_stateful_fn\u001b[0m \u001b[1;32mis\u001b[0m \u001b[1;32mnot\u001b[0m \u001b[1;32mNone\u001b[0m\u001b[1;33m:\u001b[0m\u001b[1;33m\u001b[0m\u001b[1;33m\u001b[0m\u001b[0m\n\u001b[0;32m    809\u001b[0m       \u001b[1;31m# Release the lock early so that multiple threads can perform the call\u001b[0m\u001b[1;33m\u001b[0m\u001b[1;33m\u001b[0m\u001b[1;33m\u001b[0m\u001b[0m\n",
      "\u001b[1;32m~\\anaconda3\\envs\\landmark\\lib\\site-packages\\tensorflow\\python\\eager\\function.py\u001b[0m in \u001b[0;36m__call__\u001b[1;34m(self, *args, **kwargs)\u001b[0m\n\u001b[0;32m   2827\u001b[0m     \u001b[1;32mwith\u001b[0m \u001b[0mself\u001b[0m\u001b[1;33m.\u001b[0m\u001b[0m_lock\u001b[0m\u001b[1;33m:\u001b[0m\u001b[1;33m\u001b[0m\u001b[1;33m\u001b[0m\u001b[0m\n\u001b[0;32m   2828\u001b[0m       \u001b[0mgraph_function\u001b[0m\u001b[1;33m,\u001b[0m \u001b[0margs\u001b[0m\u001b[1;33m,\u001b[0m \u001b[0mkwargs\u001b[0m \u001b[1;33m=\u001b[0m \u001b[0mself\u001b[0m\u001b[1;33m.\u001b[0m\u001b[0m_maybe_define_function\u001b[0m\u001b[1;33m(\u001b[0m\u001b[0margs\u001b[0m\u001b[1;33m,\u001b[0m \u001b[0mkwargs\u001b[0m\u001b[1;33m)\u001b[0m\u001b[1;33m\u001b[0m\u001b[1;33m\u001b[0m\u001b[0m\n\u001b[1;32m-> 2829\u001b[1;33m     \u001b[1;32mreturn\u001b[0m \u001b[0mgraph_function\u001b[0m\u001b[1;33m.\u001b[0m\u001b[0m_filtered_call\u001b[0m\u001b[1;33m(\u001b[0m\u001b[0margs\u001b[0m\u001b[1;33m,\u001b[0m \u001b[0mkwargs\u001b[0m\u001b[1;33m)\u001b[0m  \u001b[1;31m# pylint: disable=protected-access\u001b[0m\u001b[1;33m\u001b[0m\u001b[1;33m\u001b[0m\u001b[0m\n\u001b[0m\u001b[0;32m   2830\u001b[0m \u001b[1;33m\u001b[0m\u001b[0m\n\u001b[0;32m   2831\u001b[0m   \u001b[1;33m@\u001b[0m\u001b[0mproperty\u001b[0m\u001b[1;33m\u001b[0m\u001b[1;33m\u001b[0m\u001b[0m\n",
      "\u001b[1;32m~\\anaconda3\\envs\\landmark\\lib\\site-packages\\tensorflow\\python\\eager\\function.py\u001b[0m in \u001b[0;36m_filtered_call\u001b[1;34m(self, args, kwargs, cancellation_manager)\u001b[0m\n\u001b[0;32m   1841\u001b[0m       \u001b[0;31m`\u001b[0m\u001b[0margs\u001b[0m\u001b[0;31m`\u001b[0m \u001b[1;32mand\u001b[0m\u001b[0;31m \u001b[0m\u001b[0;31m`\u001b[0m\u001b[0mkwargs\u001b[0m\u001b[0;31m`\u001b[0m\u001b[1;33m.\u001b[0m\u001b[1;33m\u001b[0m\u001b[1;33m\u001b[0m\u001b[0m\n\u001b[0;32m   1842\u001b[0m     \"\"\"\n\u001b[1;32m-> 1843\u001b[1;33m     return self._call_flat(\n\u001b[0m\u001b[0;32m   1844\u001b[0m         [t for t in nest.flatten((args, kwargs), expand_composites=True)\n\u001b[0;32m   1845\u001b[0m          if isinstance(t, (ops.Tensor,\n",
      "\u001b[1;32m~\\anaconda3\\envs\\landmark\\lib\\site-packages\\tensorflow\\python\\eager\\function.py\u001b[0m in \u001b[0;36m_call_flat\u001b[1;34m(self, args, captured_inputs, cancellation_manager)\u001b[0m\n\u001b[0;32m   1921\u001b[0m         and executing_eagerly):\n\u001b[0;32m   1922\u001b[0m       \u001b[1;31m# No tape is watching; skip to running the function.\u001b[0m\u001b[1;33m\u001b[0m\u001b[1;33m\u001b[0m\u001b[1;33m\u001b[0m\u001b[0m\n\u001b[1;32m-> 1923\u001b[1;33m       return self._build_call_outputs(self._inference_function.call(\n\u001b[0m\u001b[0;32m   1924\u001b[0m           ctx, args, cancellation_manager=cancellation_manager))\n\u001b[0;32m   1925\u001b[0m     forward_backward = self._select_forward_and_backward_functions(\n",
      "\u001b[1;32m~\\anaconda3\\envs\\landmark\\lib\\site-packages\\tensorflow\\python\\eager\\function.py\u001b[0m in \u001b[0;36mcall\u001b[1;34m(self, ctx, args, cancellation_manager)\u001b[0m\n\u001b[0;32m    543\u001b[0m       \u001b[1;32mwith\u001b[0m \u001b[0m_InterpolateFunctionError\u001b[0m\u001b[1;33m(\u001b[0m\u001b[0mself\u001b[0m\u001b[1;33m)\u001b[0m\u001b[1;33m:\u001b[0m\u001b[1;33m\u001b[0m\u001b[1;33m\u001b[0m\u001b[0m\n\u001b[0;32m    544\u001b[0m         \u001b[1;32mif\u001b[0m \u001b[0mcancellation_manager\u001b[0m \u001b[1;32mis\u001b[0m \u001b[1;32mNone\u001b[0m\u001b[1;33m:\u001b[0m\u001b[1;33m\u001b[0m\u001b[1;33m\u001b[0m\u001b[0m\n\u001b[1;32m--> 545\u001b[1;33m           outputs = execute.execute(\n\u001b[0m\u001b[0;32m    546\u001b[0m               \u001b[0mstr\u001b[0m\u001b[1;33m(\u001b[0m\u001b[0mself\u001b[0m\u001b[1;33m.\u001b[0m\u001b[0msignature\u001b[0m\u001b[1;33m.\u001b[0m\u001b[0mname\u001b[0m\u001b[1;33m)\u001b[0m\u001b[1;33m,\u001b[0m\u001b[1;33m\u001b[0m\u001b[1;33m\u001b[0m\u001b[0m\n\u001b[0;32m    547\u001b[0m               \u001b[0mnum_outputs\u001b[0m\u001b[1;33m=\u001b[0m\u001b[0mself\u001b[0m\u001b[1;33m.\u001b[0m\u001b[0m_num_outputs\u001b[0m\u001b[1;33m,\u001b[0m\u001b[1;33m\u001b[0m\u001b[1;33m\u001b[0m\u001b[0m\n",
      "\u001b[1;32m~\\anaconda3\\envs\\landmark\\lib\\site-packages\\tensorflow\\python\\eager\\execute.py\u001b[0m in \u001b[0;36mquick_execute\u001b[1;34m(op_name, num_outputs, inputs, attrs, ctx, name)\u001b[0m\n\u001b[0;32m     57\u001b[0m   \u001b[1;32mtry\u001b[0m\u001b[1;33m:\u001b[0m\u001b[1;33m\u001b[0m\u001b[1;33m\u001b[0m\u001b[0m\n\u001b[0;32m     58\u001b[0m     \u001b[0mctx\u001b[0m\u001b[1;33m.\u001b[0m\u001b[0mensure_initialized\u001b[0m\u001b[1;33m(\u001b[0m\u001b[1;33m)\u001b[0m\u001b[1;33m\u001b[0m\u001b[1;33m\u001b[0m\u001b[0m\n\u001b[1;32m---> 59\u001b[1;33m     tensors = pywrap_tfe.TFE_Py_Execute(ctx._handle, device_name, op_name,\n\u001b[0m\u001b[0;32m     60\u001b[0m                                         inputs, attrs, num_outputs)\n\u001b[0;32m     61\u001b[0m   \u001b[1;32mexcept\u001b[0m \u001b[0mcore\u001b[0m\u001b[1;33m.\u001b[0m\u001b[0m_NotOkStatusException\u001b[0m \u001b[1;32mas\u001b[0m \u001b[0me\u001b[0m\u001b[1;33m:\u001b[0m\u001b[1;33m\u001b[0m\u001b[1;33m\u001b[0m\u001b[0m\n",
      "\u001b[1;31mKeyboardInterrupt\u001b[0m: "
     ]
    }
   ],
   "source": [
    "hist = model.fit(train_ds, validation_data=val_ds, epochs=100, callbacks=callbacks_list)"
   ]
  },
  {
   "cell_type": "code",
   "execution_count": null,
   "id": "04db6666",
   "metadata": {},
   "outputs": [],
   "source": [
    "plt.figure(figsize=(12, 10))\n",
    "plt.plot(hist.history['loss'], label='train')\n",
    "plt.plot(hist.history['val_loss'], label='val')\n",
    "plt.legend()\n",
    "plt.title('imagenet weight Loss', size=12)\n",
    "plt.savefig('./loss_image/None_weight.png')"
   ]
  },
  {
   "cell_type": "code",
   "execution_count": null,
   "id": "09f4b39f",
   "metadata": {},
   "outputs": [],
   "source": [
    "df = pd.DataFrame({\n",
    "    'train_loss': hist.history['loss'],\n",
    "    'val_loss': hist.history['val_loss']\n",
    "})\n",
    "df.to_csv('./loss/detector_None_loss.csv', index=False)"
   ]
  }
 ],
 "metadata": {
  "kernelspec": {
   "display_name": "Python 3 (ipykernel)",
   "language": "python",
   "name": "python3"
  },
  "language_info": {
   "codemirror_mode": {
    "name": "ipython",
    "version": 3
   },
   "file_extension": ".py",
   "mimetype": "text/x-python",
   "name": "python",
   "nbconvert_exporter": "python",
   "pygments_lexer": "ipython3",
   "version": "3.8.2"
  }
 },
 "nbformat": 4,
 "nbformat_minor": 5
}
